Workbook

Sheet Expenses
A1: DriveCam
A2: Initial Capital | B2: 100000
A4: This sheet defines your expenses including salaries, office (if applicable), advertising (if applicable) and operations. The monthly cash burn (how much you spend each month), and runway (how many months you have before running out of cash) is calculated for you. Determine when and if you will pay yourselves as founders, if you will have an office, and a educated estimate at your operating expenses to model the expenses for the duration of this model.
A7: Salaries: | B7: Yellow highligted cells are inputs, all others are calculated for you
A8: Title | B8: Annual Salary | C8: Fringe benefits | D8: Salary + Fringe | E8: Date Hired | F8: 46037 | G8: 46068 | H8: 46096 | I8: Q1 2026 | J8: 46127 | K8: 46157 | L8: 46188 | M8: Q2 2026 | N8: 46218 | O8: 46249 | P8: 46280 | Q8: Q3 2026 | R8: 46310 | S8: 46341 | T8: 46371 | U8: Q4 2026 | V8: FY 2026 | W8: 46402 | X8: 46433 | Y8: 46461 | Z8: Q1 2027 | AA8: 46492 | AB8: 46522 | AC8: 46553 | AD8: Q2 2027 | AE8: 46583 | AF8: 46614 | AG8: 46645 | AH8: Q3 2027 | AI8: 46675 | AJ8: 46706 | AK8: 46736 | AL8: Q4 2027 | AM8: FY 2027
A9: CEO | B9: 50000 | C9: 0.09 | D9: =B9+(B9*C9) -> 54500 | E9: 46204 | G9: =IF($E9<=G$8, $D9/12, 0) -> 0 | H9: =IF($E9<=H$8, $D9/12, 0) -> 0 | I9: =SUM(F9:H9) -> 0 | J9: =IF($E9<=J$8, $D9/12, 0) -> 0 | K9: =IF($E9<=K$8, $D9/12, 0) -> 0 | L9: =IF($E9<=L$8, $D9/12, 0) -> 0 | M9: =SUM(J9:L9) -> 0 | N9: =IF($E9<=N$8, $D9/12, 0) -> 4541.6667 | O9: =IF($E9<=O$8, $D9/12, 0) -> 4541.6667 | P9: =IF($E9<=P$8, $D9/12, 0) -> 4541.6667 | Q9: =SUM(N9:P9) -> 13625 | R9: =IF($E9<=R$8, $D9/12, 0) -> 4541.6667 | S9: =IF($E9<=S$8, $D9/12, 0) -> 4541.6667 | T9: =IF($E9<=T$8, $D9/12, 0) -> 4541.6667 | U9: =SUM(R9:T9) -> 13625 | V9: =I9+M9+Q9+U9 -> 27250 | W9: =IF($E9<=W$8, $D9/12, 0) -> 4541.6667 | X9: =IF($E9<=X$8, $D9/12, 0) -> 4541.6667 | Y9: =IF($E9<=Y$8, $D9/12, 0) -> 4541.6667 | Z9: =SUM(W9:Y9) -> 13625 | AA9: =IF($E9<=AA$8, $D9/12, 0) -> 4541.6667 | AB9: =IF($E9<=AB$8, $D9/12, 0) -> 4541.6667 | AC9: =IF($E9<=AC$8, $D9/12, 0) -> 4541.6667 | AD9: =SUM(AA9:AC9) -> 13625 | AE9: =IF($E9<=AE$8, $D9/12, 0) -> 4541.6667 | AF9: =IF($E9<=AF$8, $D9/12, 0) -> 4541.6667 | AG9: =IF($E9<=AG$8, $D9/12, 0) -> 4541.6667 | AH9: =SUM(AE9:AG9) -> 13625 | AI9: =IF($E9<=AI$8, $D9/12, 0) -> 4541.6667 | AJ9: =IF($E9<=AJ$8, $D9/12, 0) -> 4541.6667 | AK9: =IF($E9<=AK$8, $D9/12, 0) -> 4541.6667 | AL9: =SUM(AI9:AK9) -> 13625 | AM9: =Z9+AD9+AH9+AL9 -> 54500
A10: CTO | B10: 50000 | C10: 0.09 | D10: =B10+(B10*C10) -> 54500 | E10: 46204 | F10: =IF($E9<=F$8, $D9/12, 0) -> 0 | G10: =IF($E10<=G$8, $D10/12, 0) -> 0 | H10: =IF($E10<=H$8, $D10/12, 0) -> 0 | I10: =SUM(F10:H10) -> 0 | J10: =IF($E10<=J$8, $D10/12, 0) -> 0 | K10: =IF($E10<=K$8, $D10/12, 0) -> 0 | L10: =IF($E10<=L$8, $D10/12, 0) -> 0 | M10: =SUM(J10:L10) -> 0 | N10: =IF($E10<=N$8, $D10/12, 0) -> 4541.6667 | O10: =IF($E10<=O$8, $D10/12, 0) -> 4541.6667 | P10: =IF($E10<=P$8, $D10/12, 0) -> 4541.6667 | Q10: =SUM(N10:P10) -> 13625 | R10: =IF($E10<=R$8, $D10/12, 0) -> 4541.6667 | S10: =IF($E10<=S$8, $D10/12, 0) -> 4541.6667 | T10: =IF($E10<=T$8, $D10/12, 0) -> 4541.6667 | U10: =SUM(R10:T10) -> 13625 | V10: =I10+M10+Q10+U10 -> 27250 | W10: =IF($E9<=W$8, $D9/12, 0) -> 4541.6667 | X10: =IF($E10<=X$8, $D10/12, 0) -> 4541.6667 | Y10: =IF($E10<=Y$8, $D10/12, 0) -> 4541.6667 | Z10: =SUM(W10:Y10) -> 13625 | AA10: =IF($E10<=AA$8, $D10/12, 0) -> 4541.6667 | AB10: =IF($E10<=AB$8, $D10/12, 0) -> 4541.6667 | AC10: =IF($E10<=AC$8, $D10/12, 0) -> 4541.6667 | AD10: =SUM(AA10:AC10) -> 13625 | AE10: =IF($E10<=AE$8, $D10/12, 0) -> 4541.6667 | AF10: =IF($E10<=AF$8, $D10/12, 0) -> 4541.6667 | AG10: =IF($E10<=AG$8, $D10/12, 0) -> 4541.6667 | AH10: =SUM(AE10:AG10) -> 13625 | AI10: =IF($E10<=AI$8, $D10/12, 0) -> 4541.6667 | AJ10: =IF($E10<=AJ$8, $D10/12, 0) -> 4541.6667 | AK10: =IF($E10<=AK$8, $D10/12, 0) -> 4541.6667 | AL10: =SUM(AI10:AK10) -> 13625 | AM10: =Z10+AD10+AH10+AL10 -> 54500
A11: Engineer 1 | B11: 50000 | C11: 0.09 | D11: =B11+(B11*C11) -> 54500 | E11: 46023 | F11: =IF($E11<=F$8, $D11/12, 0) -> 4541.6667 | G11: =IF($E11<=G$8, $D11/12, 0) -> 4541.6667 | H11: =IF($E11<=H$8, $D11/12, 0) -> 4541.6667 | I11: =SUM(F11:H11) -> 13625 | J11: =IF($E11<=J$8, $D11/12, 0) -> 4541.6667 | K11: =IF($E11<=K$8, $D11/12, 0) -> 4541.6667 | L11: =IF($E11<=L$8, $D11/12, 0) -> 4541.6667 | M11: =SUM(J11:L11) -> 13625 | N11: =IF($E11<=N$8, $D11/12, 0) -> 4541.6667 | O11: =IF($E11<=O$8, $D11/12, 0) -> 4541.6667 | P11: =IF($E11<=P$8, $D11/12, 0) -> 4541.6667 | Q11: =SUM(N11:P11) -> 13625 | R11: =IF($E11<=R$8, $D11/12, 0) -> 4541.6667 | S11: =IF($E11<=S$8, $D11/12, 0) -> 4541.6667 | T11: =IF($E11<=T$8, $D11/12, 0) -> 4541.6667 | U11: =SUM(R11:T11) -> 13625 | V11: =I11+M11+Q11+U11 -> 54500 | W11: =IF($E11<=W$8, $D11/12, 0) -> 4541.6667 | X11: =IF($E11<=X$8, $D11/12, 0) -> 4541.6667 | Y11: =IF($E11<=Y$8, $D11/12, 0) -> 4541.6667 | Z11: =SUM(W11:Y11) -> 13625 | AA11: =IF($E11<=AA$8, $D11/12, 0) -> 4541.6667 | AB11: =IF($E11<=AB$8, $D11/12, 0) -> 4541.6667 | AC11: =IF($E11<=AC$8, $D11/12, 0) -> 4541.6667 | AD11: =SUM(AA11:AC11) -> 13625 | AE11: =IF($E11<=AE$8, $D11/12, 0) -> 4541.6667 | AF11: =IF($E11<=AF$8, $D11/12, 0) -> 4541.6667 | AG11: =IF($E11<=AG$8, $D11/12, 0) -> 4541.6667 | AH11: =SUM(AE11:AG11) -> 13625 | AI11: =IF($E11<=AI$8, $D11/12, 0) -> 4541.6667 | AJ11: =IF($E11<=AJ$8, $D11/12, 0) -> 4541.6667 | AK11: =IF($E11<=AK$8, $D11/12, 0) -> 4541.6667 | AL11: =SUM(AI11:AK11) -> 13625 | AM11: =Z11+AD11+AH11+AL11 -> 54500
A12: Engineer 2 | B12: 0 | C12: 0.09 | D12: =B12+(B12*C12) -> 0 | F12: =IF($E12<=F$8, $D12/12, 0) -> 0 | G12: =IF($E12<=G$8, $D12/12, 0) -> 0 | H12: =IF($E12<=H$8, $D12/12, 0) -> 0 | I12: =SUM(F12:H12) -> 0 | J12: =IF($E12<=J$8, $D12/12, 0) -> 0 | K12: =IF($E12<=K$8, $D12/12, 0) -> 0 | L12: =IF($E12<=L$8, $D12/12, 0) -> 0 | M12: =SUM(J12:L12) -> 0 | N12: =IF($E12<=N$8, $D12/12, 0) -> 0 | O12: =IF($E12<=O$8, $D12/12, 0) -> 0 | P12: =IF($E12<=P$8, $D12/12, 0) -> 0 | Q12: =SUM(N12:P12) -> 0 | R12: =IF($E12<=R$8, $D12/12, 0) -> 0 | S12: =IF($E12<=S$8, $D12/12, 0) -> 0 | T12: =IF($E12<=T$8, $D12/12, 0) -> 0 | U12: =SUM(R12:T12) -> 0 | V12: =I12+M12+Q12+U12 -> 0 | W12: =IF($E12<=W$8, $D12/12, 0) -> 0 | X12: =IF($E12<=X$8, $D12/12, 0) -> 0 | Y12: =IF($E12<=Y$8, $D12/12, 0) -> 0 | Z12: =SUM(W12:Y12) -> 0 | AA12: =IF($E12<=AA$8, $D12/12, 0) -> 0 | AB12: =IF($E12<=AB$8, $D12/12, 0) -> 0 | AC12: =IF($E12<=AC$8, $D12/12, 0) -> 0 | AD12: =SUM(AA12:AC12) -> 0 | AE12: =IF($E12<=AE$8, $D12/12, 0) -> 0 | AF12: =IF($E12<=AF$8, $D12/12, 0) -> 0 | AG12: =IF($E12<=AG$8, $D12/12, 0) -> 0 | AH12: =SUM(AE12:AG12) -> 0 | AI12: =IF($E12<=AI$8, $D12/12, 0) -> 0 | AJ12: =IF($E12<=AJ$8, $D12/12, 0) -> 0 | AK12: =IF($E12<=AK$8, $D12/12, 0) -> 0 | AL12: =SUM(AI12:AK12) -> 0 | AM12: =Z12+AD12+AH12+AL12 -> 0
A13: Designer | B13: 0 | C13: 0.09 | D13: =B13+(B13*C13) -> 0 | F13: =IF($E13<=F$8, $D13/12, 0) -> 0 | G13: =IF($E13<=G$8, $D13/12, 0) -> 0 | H13: =IF($E13<=H$8, $D13/12, 0) -> 0 | I13: =SUM(F13:H13) -> 0 | J13: =IF($E13<=J$8, $D13/12, 0) -> 0 | K13: =IF($E13<=K$8, $D13/12, 0) -> 0 | L13: =IF($E13<=L$8, $D13/12, 0) -> 0 | M13: =SUM(J13:L13) -> 0 | N13: =IF($E13<=N$8, $D13/12, 0) -> 0 | O13: =IF($E13<=O$8, $D13/12, 0) -> 0 | P13: =IF($E13<=P$8, $D13/12, 0) -> 0 | Q13: =SUM(N13:P13) -> 0 | R13: =IF($E13<=R$8, $D13/12, 0) -> 0 | S13: =IF($E13<=S$8, $D13/12, 0) -> 0 | T13: =IF($E13<=T$8, $D13/12, 0) -> 0 | U13: =SUM(R13:T13) -> 0 | V13: =I13+M13+Q13+U13 -> 0 | W13: =IF($E13<=W$8, $D13/12, 0) -> 0 | X13: =IF($E13<=X$8, $D13/12, 0) -> 0 | Y13: =IF($E13<=Y$8, $D13/12, 0) -> 0 | Z13: =SUM(W13:Y13) -> 0 | AA13: =IF($E13<=AA$8, $D13/12, 0) -> 0 | AB13: =IF($E13<=AB$8, $D13/12, 0) -> 0 | AC13: =IF($E13<=AC$8, $D13/12, 0) -> 0 | AD13: =SUM(AA13:AC13) -> 0 | AE13: =IF($E13<=AE$8, $D13/12, 0) -> 0 | AF13: =IF($E13<=AF$8, $D13/12, 0) -> 0 | AG13: =IF($E13<=AG$8, $D13/12, 0) -> 0 | AH13: =SUM(AE13:AG13) -> 0 | AI13: =IF($E13<=AI$8, $D13/12, 0) -> 0 | AJ13: =IF($E13<=AJ$8, $D13/12, 0) -> 0 | AK13: =IF($E13<=AK$8, $D13/12, 0) -> 0 | AL13: =SUM(AI13:AK13) -> 0 | AM13: =Z13+AD13+AH13+AL13 -> 0
A14: B2B Sales Manager 1 | B14: 0 | C14: 0.09 | D14: =B14+(B14*C14) -> 0 | F14: =IF($E14<=F$8, $D14/12, 0) -> 0 | G14: =IF($E14<=G$8, $D14/12, 0) -> 0 | H14: =IF($E14<=H$8, $D14/12, 0) -> 0 | I14: =SUM(F14:H14) -> 0 | J14: =IF($E14<=J$8, $D14/12, 0) -> 0 | K14: =IF($E14<=K$8, $D14/12, 0) -> 0 | L14: =IF($E14<=L$8, $D14/12, 0) -> 0 | M14: =SUM(J14:L14) -> 0 | N14: =IF($E14<=N$8, $D14/12, 0) -> 0 | O14: =IF($E14<=O$8, $D14/12, 0) -> 0 | P14: =IF($E14<=P$8, $D14/12, 0) -> 0 | Q14: =SUM(N14:P14) -> 0 | R14: =IF($E14<=R$8, $D14/12, 0) -> 0 | S14: =IF($E14<=S$8, $D14/12, 0) -> 0 | T14: =IF($E14<=T$8, $D14/12, 0) -> 0 | U14: =SUM(R14:T14) -> 0 | V14: =I14+M14+Q14+U14 -> 0 | W14: =IF($E14<=W$8, $D14/12, 0) -> 0 | X14: =IF($E14<=X$8, $D14/12, 0) -> 0 | Y14: =IF($E14<=Y$8, $D14/12, 0) -> 0 | Z14: =SUM(W14:Y14) -> 0 | AA14: =IF($E14<=AA$8, $D14/12, 0) -> 0 | AB14: =IF($E14<=AB$8, $D14/12, 0) -> 0 | AC14: =IF($E14<=AC$8, $D14/12, 0) -> 0 | AD14: =SUM(AA14:AC14) -> 0 | AE14: =IF($E14<=AE$8, $D14/12, 0) -> 0 | AF14: =IF($E14<=AF$8, $D14/12, 0) -> 0 | AG14: =IF($E14<=AG$8, $D14/12, 0) -> 0 | AH14: =SUM(AE14:AG14) -> 0 | AI14: =IF($E14<=AI$8, $D14/12, 0) -> 0 | AJ14: =IF($E14<=AJ$8, $D14/12, 0) -> 0 | AK14: =IF($E14<=AK$8, $D14/12, 0) -> 0 | AL14: =SUM(AI14:AK14) -> 0 | AM14: =Z14+AD14+AH14+AL14 -> 0
A15: B2B Sales Manager 2 | B15: 0 | C15: 0.09 | D15: =B15+(B15*C15) -> 0 | F15: =IF($E15<=F$8, $D15/12, 0) -> 0 | G15: =IF($E15<=G$8, $D15/12, 0) -> 0 | H15: =IF($E15<=H$8, $D15/12, 0) -> 0 | I15: =SUM(F15:H15) -> 0 | J15: =IF($E15<=J$8, $D15/12, 0) -> 0 | K15: =IF($E15<=K$8, $D15/12, 0) -> 0 | L15: =IF($E15<=L$8, $D15/12, 0) -> 0 | M15: =SUM(J15:L15) -> 0 | N15: =IF($E15<=N$8, $D15/12, 0) -> 0 | O15: =IF($E15<=O$8, $D15/12, 0) -> 0 | P15: =IF($E15<=P$8, $D15/12, 0) -> 0 | Q15: =SUM(N15:P15) -> 0 | R15: =IF($E15<=R$8, $D15/12, 0) -> 0 | S15: =IF($E15<=S$8, $D15/12, 0) -> 0 | T15: =IF($E15<=T$8, $D15/12, 0) -> 0 | U15: =SUM(R15:T15) -> 0 | V15: =I15+M15+Q15+U15 -> 0 | W15: =IF($E15<=W$8, $D15/12, 0) -> 0 | X15: =IF($E15<=X$8, $D15/12, 0) -> 0 | Y15: =IF($E15<=Y$8, $D15/12, 0) -> 0 | Z15: =SUM(W15:Y15) -> 0 | AA15: =IF($E15<=AA$8, $D15/12, 0) -> 0 | AB15: =IF($E15<=AB$8, $D15/12, 0) -> 0 | AC15: =IF($E15<=AC$8, $D15/12, 0) -> 0 | AD15: =SUM(AA15:AC15) -> 0 | AE15: =IF($E15<=AE$8, $D15/12, 0) -> 0 | AF15: =IF($E15<=AF$8, $D15/12, 0) -> 0 | AG15: =IF($E15<=AG$8, $D15/12, 0) -> 0 | AH15: =SUM(AE15:AG15) -> 0 | AI15: =IF($E15<=AI$8, $D15/12, 0) -> 0 | AJ15: =IF($E15<=AJ$8, $D15/12, 0) -> 0 | AK15: =IF($E15<=AK$8, $D15/12, 0) -> 0 | AL15: =SUM(AI15:AK15) -> 0 | AM15: =Z15+AD15+AH15+AL15 -> 0
A16: Add more | B16: 0 | C16: 0.09 | D16: =B16+(B16*C16) -> 0 | F16: =IF($E16<=F$8, $D16/12, 0) -> 0 | G16: =IF($E16<=G$8, $D16/12, 0) -> 0 | H16: =IF($E16<=H$8, $D16/12, 0) -> 0 | I16: =SUM(F16:H16) -> 0 | J16: =IF($E16<=J$8, $D16/12, 0) -> 0 | K16: =IF($E16<=K$8, $D16/12, 0) -> 0 | L16: =IF($E16<=L$8, $D16/12, 0) -> 0 | M16: =SUM(J16:L16) -> 0 | N16: =IF($E16<=N$8, $D16/12, 0) -> 0 | O16: =IF($E16<=O$8, $D16/12, 0) -> 0 | P16: =IF($E16<=P$8, $D16/12, 0) -> 0 | Q16: =SUM(N16:P16) -> 0 | R16: =IF($E16<=R$8, $D16/12, 0) -> 0 | S16: =IF($E16<=S$8, $D16/12, 0) -> 0 | T16: =IF($E16<=T$8, $D16/12, 0) -> 0 | U16: =SUM(R16:T16) -> 0 | V16: =I16+M16+Q16+U16 -> 0 | W16: =IF($E16<=W$8, $D16/12, 0) -> 0 | X16: =IF($E16<=X$8, $D16/12, 0) -> 0 | Y16: =IF($E16<=Y$8, $D16/12, 0) -> 0 | Z16: =SUM(W16:Y16) -> 0 | AA16: =IF($E16<=AA$8, $D16/12, 0) -> 0 | AB16: =IF($E16<=AB$8, $D16/12, 0) -> 0 | AC16: =IF($E16<=AC$8, $D16/12, 0) -> 0 | AD16: =SUM(AA16:AC16) -> 0 | AE16: =IF($E16<=AE$8, $D16/12, 0) -> 0 | AF16: =IF($E16<=AF$8, $D16/12, 0) -> 0 | AG16: =IF($E16<=AG$8, $D16/12, 0) -> 0 | AH16: =SUM(AE16:AG16) -> 0 | AI16: =IF($E16<=AI$8, $D16/12, 0) -> 0 | AJ16: =IF($E16<=AJ$8, $D16/12, 0) -> 0 | AK16: =IF($E16<=AK$8, $D16/12, 0) -> 0 | AL16: =SUM(AI16:AK16) -> 0 | AM16: =Z16+AD16+AH16+AL16 -> 0
A17: Add more | B17: 0 | C17: 0.09 | D17: =B17+(B17*C17) -> 0 | F17: =IF($E17<=F$8, $D17/12, 0) -> 0 | G17: =IF($E17<=G$8, $D17/12, 0) -> 0 | H17: =IF($E17<=H$8, $D17/12, 0) -> 0 | I17: =SUM(F17:H17) -> 0 | J17: =IF($E17<=J$8, $D17/12, 0) -> 0 | K17: =IF($E17<=K$8, $D17/12, 0) -> 0 | L17: =IF($E17<=L$8, $D17/12, 0) -> 0 | M17: =SUM(J17:L17) -> 0 | N17: =IF($E17<=N$8, $D17/12, 0) -> 0 | O17: =IF($E17<=O$8, $D17/12, 0) -> 0 | P17: =IF($E17<=P$8, $D17/12, 0) -> 0 | Q17: =SUM(N17:P17) -> 0 | R17: =IF($E17<=R$8, $D17/12, 0) -> 0 | S17: =IF($E17<=S$8, $D17/12, 0) -> 0 | T17: =IF($E17<=T$8, $D17/12, 0) -> 0 | U17: =SUM(R17:T17) -> 0 | V17: =I17+M17+Q17+U17 -> 0 | W17: =IF($E17<=W$8, $D17/12, 0) -> 0 | X17: =IF($E17<=X$8, $D17/12, 0) -> 0 | Y17: =IF($E17<=Y$8, $D17/12, 0) -> 0 | Z17: =SUM(W17:Y17) -> 0 | AA17: =IF($E17<=AA$8, $D17/12, 0) -> 0 | AB17: =IF($E17<=AB$8, $D17/12, 0) -> 0 | AC17: =IF($E17<=AC$8, $D17/12, 0) -> 0 | AD17: =SUM(AA17:AC17) -> 0 | AE17: =IF($E17<=AE$8, $D17/12, 0) -> 0 | AF17: =IF($E17<=AF$8, $D17/12, 0) -> 0 | AG17: =IF($E17<=AG$8, $D17/12, 0) -> 0 | AH17: =SUM(AE17:AG17) -> 0 | AI17: =IF($E17<=AI$8, $D17/12, 0) -> 0 | AJ17: =IF($E17<=AJ$8, $D17/12, 0) -> 0 | AK17: =IF($E17<=AK$8, $D17/12, 0) -> 0 | AL17: =SUM(AI17:AK17) -> 0 | AM17: =Z17+AD17+AH17+AL17 -> 0
A18: Add more | B18: 0 | C18: 0.09 | D18: =B18+(B18*C18) -> 0 | F18: =IF($E18<=F$8, $D18/12, 0) -> 0 | G18: =IF($E18<=G$8, $D18/12, 0) -> 0 | H18: =IF($E18<=H$8, $D18/12, 0) -> 0 | I18: =SUM(F18:H18) -> 0 | J18: =IF($E18<=J$8, $D18/12, 0) -> 0 | K18: =IF($E18<=K$8, $D18/12, 0) -> 0 | L18: =IF($E18<=L$8, $D18/12, 0) -> 0 | M18: =SUM(J18:L18) -> 0 | N18: =IF($E18<=N$8, $D18/12, 0) -> 0 | O18: =IF($E18<=O$8, $D18/12, 0) -> 0 | P18: =IF($E18<=P$8, $D18/12, 0) -> 0 | Q18: =SUM(N18:P18) -> 0 | R18: =IF($E18<=R$8, $D18/12, 0) -> 0 | S18: =IF($E18<=S$8, $D18/12, 0) -> 0 | T18: =IF($E18<=T$8, $D18/12, 0) -> 0 | U18: =SUM(R18:T18) -> 0 | V18: =I18+M18+Q18+U18 -> 0 | W18: =IF($E18<=W$8, $D18/12, 0) -> 0 | X18: =IF($E18<=X$8, $D18/12, 0) -> 0 | Y18: =IF($E18<=Y$8, $D18/12, 0) -> 0 | Z18: =SUM(W18:Y18) -> 0 | AA18: =IF($E18<=AA$8, $D18/12, 0) -> 0 | AB18: =IF($E18<=AB$8, $D18/12, 0) -> 0 | AC18: =IF($E18<=AC$8, $D18/12, 0) -> 0 | AD18: =SUM(AA18:AC18) -> 0 | AE18: =IF($E18<=AE$8, $D18/12, 0) -> 0 | AF18: =IF($E18<=AF$8, $D18/12, 0) -> 0 | AG18: =IF($E18<=AG$8, $D18/12, 0) -> 0 | AH18: =SUM(AE18:AG18) -> 0 | AI18: =IF($E18<=AI$8, $D18/12, 0) -> 0 | AJ18: =IF($E18<=AJ$8, $D18/12, 0) -> 0 | AK18: =IF($E18<=AK$8, $D18/12, 0) -> 0 | AL18: =SUM(AI18:AK18) -> 0 | AM18: =Z18+AD18+AH18+AL18 -> 0
A19: Total: | B19: =SUM(B9:B18) -> 150000 | F19: =SUM(F10:F18) -> 4541.6667 | G19: =SUM(G9:G18) -> 4541.6667 | H19: =SUM(H9:H18) -> 4541.6667 | I19: =SUM(I9:I18) -> 13625 | J19: =SUM(J9:J18) -> 4541.6667 | K19: =SUM(K9:K18) -> 4541.6667 | L19: =SUM(L9:L18) -> 4541.6667 | M19: =SUM(M9:M18) -> 13625 | N19: =SUM(N9:N18) -> 13625 | ... AM19: =SUM(AM9:AM18) -> 163500
A20: Number of people in team | F20: =COUNTIF(F10:F18,">0") -> 1 | G20: =COUNTIF(G9:G18,">0") -> 1 | H20: =COUNTIF(H9:H18,">0") -> 1 | I20: =COUNTIF(I9:I18,">0") -> 1 | J20: =COUNTIF(J9:J18,">0") -> 1 | K20: =COUNTIF(K9:K18,">0") -> 1 | L20: =COUNTIF(L9:L18,">0") -> 1 | M20: =COUNTIF(M9:M18,">0") -> 1 | N20: =COUNTIF(N9:N18,">0") -> 3 | ... V20: =COUNTIF(V9:V18,">0") -> 3 | W20: =COUNTIF(W10:W18,">0") -> 2 | X20: =COUNTIF(X9:X18,">0") -> 3 | Y20: =COUNTIF(Y9:Y18,">0") -> 3 | Z20: =COUNTIF(Z9:Z18,">0") -> 3 | AA20: =COUNTIF(AA9:AA18,">0") -> 3 | AB20: =COUNTIF(AB9:AB18,">0") -> 3 | AC20: =COUNTIF(AC9:AC18,">0") -> 3 | AD20: =COUNTIF(AD9:AD18,">0") -> 3 | AE20: =COUNTIF(AE9:AE18,">0") -> 3 | ... AM20: =COUNTIF(AM9:AM18,">0") -> 3
A23: General Expenses:
A24: Title | B24: Annual | E24: Start Date | F24: 46037 | G24: 46068 | H24: 46096 | I24: Q1 2025 | J24: 46127 | K24: 46157 | L24: 46188 | M24: Q2 2026 | N24: 46218 | O24: 46249 | P24: 46280 | Q24: Q3 2026 | R24: 46310 | S24: 46341 | T24: 46371 | U24: Q4 2026 | V24: FY 2026 | W24: 46402 | X24: 46433 | Y24: 46461 | Z24: Q1 2027 | AA24: 46492 | AB24: 46522 | AC24: 46553 | AD24: Q2 2027 | AE24: 46583 | AF24: 46614 | AG24: 46645 | AH24: Q3 2027 | AI24: 46675 | AJ24: 46706 | AK24: 46736 | AL24: Q4 2027 | AM24: FY 2027
A25: Miscellanious Expenses | B25: 1500 | E25: 46023 | F25: =IF($E25<=F$24, $B25/12, 0) -> 125 | G25: =IF($E25<=G$24, $B25/12, 0) -> 125 | H25: =IF($E25<=H$24, $B25/12, 0) -> 125 | I25: =SUM(F25:H25) -> 375 | J25: =IF($E25<=J$24, $B25/12, 0) -> 125 | K25: =IF($E25<=K$24, $B25/12, 0) -> 125 | L25: =IF($E25<=L$24, $B25/12, 0) -> 125 | M25: =SUM(J25:L25) -> 375 | N25: =IF($E25<=N$24, $B25/12, 0) -> 125 | O25: =IF($E25<=O$24, $B25/12, 0) -> 125 | P25: =IF($E25<=P$24, $B25/12, 0) -> 125 | Q25: =SUM(N25:P25) -> 375 | R25: =IF($E25<=R$24, $B25/12, 0) -> 125 | S25: =IF($E25<=S$24, $B25/12, 0) -> 125 | T25: =IF($E25<=T$24, $B25/12, 0) -> 125 | U25: =SUM(R25:T25) -> 375 | V25: =I25+M25+Q25+U25 -> 1500 | W25: =IF($E25<=W$24, $B25/12, 0) -> 125 | X25: =IF($E25<=X$24, $B25/12, 0) -> 125 | Y25: =IF($E25<=Y$24, $B25/12, 0) -> 125 | Z25: =SUM(W25:Y25) -> 375 | AA25: =IF($E25<=AA$24, $B25/12, 0) -> 125 | AB25: =IF($E25<=AB$24, $B25/12, 0) -> 125 | AC25: =IF($E25<=AC$24, $B25/12, 0) -> 125 | AD25: =SUM(AA25:AC25) -> 375 | AE25: =IF($E25<=AE$24, $B25/12, 0) -> 125 | AF25: =IF($E25<=AF$24, $B25/12, 0) -> 125 | AG25: =IF($E25<=AG$24, $B25/12, 0) -> 125 | AH25: =SUM(AE25:AG25) -> 375 | AI25: =IF($E25<=AI$24, $B25/12, 0) -> 125 | AJ25: =IF($E25<=AJ$24, $B25/12, 0) -> 125 | AK25: =IF($E25<=AK$24, $B25/12, 0) -> 125 | AL25: =SUM(AI25:AK25) -> 375 | AM25: =Z25+AD25+AH25+AL25 -> 1500
A26: Add more | B26: 0 | E26: 45658 | F26: =IF($E26<=F$24, $B26/12, 0) -> 0 | G26: =IF($E26<=G$24, $B26/12, 0) -> 0 | H26: =IF($E26<=H$24, $B26/12, 0) -> 0 | I26: =SUM(F26:H26) -> 0 | J26: =IF($E26<=J$24, $B26/12, 0) -> 0 | K26: =IF($E26<=K$24, $B26/12, 0) -> 0 | L26: =IF($E26<=L$24, $B26/12, 0) -> 0 | M26: =SUM(J26:L26) -> 0 | N26: =IF($E26<=N$24, $B26/12, 0) -> 0 | O26: =IF($E26<=O$24, $B26/12, 0) -> 0 | P26: =IF($E26<=P$24, $B26/12, 0) -> 0 | Q26: =SUM(N26:P26) -> 0 | R26: =IF($E26<=R$24, $B26/12, 0) -> 0 | S26: =IF($E26<=S$24, $B26/12, 0) -> 0 | T26: =IF($E26<=T$24, $B26/12, 0) -> 0 | U26: =SUM(R26:T26) -> 0 | V26: =I26+M26+Q26+U26 -> 0 | W26: =IF($E26<=W$24, $B26/12, 0) -> 0 | X26: =IF($E26<=X$24, $B26/12, 0) -> 0 | Y26: =IF($E26<=Y$24, $B26/12, 0) -> 0 | Z26: =SUM(W26:Y26) -> 0 | AA26: =IF($E26<=AA$24, $B26/12, 0) -> 0 | AB26: =IF($E26<=AB$24, $B26/12, 0) -> 0 | AC26: =IF($E26<=AC$24, $B26/12, 0) -> 0 | AD26: =SUM(AA26:AC26) -> 0 | AE26: =IF($E26<=AE$24, $B26/12, 0) -> 0 | AF26: =IF($E26<=AF$24, $B26/12, 0) -> 0 | AG26: =IF($E26<=AG$24, $B26/12, 0) -> 0 | AH26: =SUM(AE26:AG26) -> 0 | AI26: =IF($E26<=AI$24, $B26/12, 0) -> 0 | AJ26: =IF($E26<=AJ$24, $B26/12, 0) -> 0 | AK26: =IF($E26<=AK$24, $B26/12, 0) -> 0 | AL26: =SUM(AI26:AK26) -> 0 | AM26: =Z26+AD26+AH26+AL26 -> 0
A27: Add more | B27: 0 | E27: 45658 | F27: =IF($E27<=F$24, $B27/12, 0) -> 0 | G27: =IF($E27<=G$24, $B27/12, 0) -> 0 | H27: =IF($E27<=H$24, $B27/12, 0) -> 0 | I27: =SUM(F27:H27) -> 0 | J27: =IF($E27<=J$24, $B27/12, 0) -> 0 | K27: =IF($E27<=K$24, $B27/12, 0) -> 0 | L27: =IF($E27<=L$24, $B27/12, 0) -> 0 | M27: =SUM(J27:L27) -> 0 | N27: =IF($E27<=N$24, $B27/12, 0) -> 0 | O27: =IF($E27<=O$24, $B27/12, 0) -> 0 | P27: =IF($E27<=P$24, $B27/12, 0) -> 0 | Q27: =SUM(N27:P27) -> 0 | R27: =IF($E27<=R$24, $B27/12, 0) -> 0 | S27: =IF($E27<=S$24, $B27/12, 0) -> 0 | T27: =IF($E27<=T$24, $B27/12, 0) -> 0 | U27: =SUM(R27:T27) -> 0 | V27: =I27+M27+Q27+U27 -> 0 | W27: =IF($E27<=W$24, $B27/12, 0) -> 0 | X27: =IF($E27<=X$24, $B27/12, 0) -> 0 | Y27: =IF($E27<=Y$24, $B27/12, 0) -> 0 | Z27: =SUM(W27:Y27) -> 0 | AA27: =IF($E27<=AA$24, $B27/12, 0) -> 0 | AB27: =IF($E27<=AB$24, $B27/12, 0) -> 0 | AC27: =IF($E27<=AC$24, $B27/12, 0) -> 0 | AD27: =SUM(AA27:AC27) -> 0 | AE27: =IF($E27<=AE$24, $B27/12, 0) -> 0 | AF27: =IF($E27<=AF$24, $B27/12, 0) -> 0 | AG27: =IF($E27<=AG$24, $B27/12, 0) -> 0 | AH27: =SUM(AE27:AG27) -> 0 | AI27: =IF($E27<=AI$24, $B27/12, 0) -> 0 | AJ27: =IF($E27<=AJ$24, $B27/12, 0) -> 0 | AK27: =IF($E27<=AK$24, $B27/12, 0) -> 0 | AL27: =SUM(AI27:AK27) -> 0 | AM27: =Z27+AD27+AH27+AL27 -> 0
A28: Add more | B28: 0 | E28: 45658 | F28: =IF($E28<=F$24, $B28/12, 0) -> 0 | G28: =IF($E28<=G$24, $B28/12, 0) -> 0 | H28: =IF($E28<=H$24, $B28/12, 0) -> 0 | I28: =SUM(F28:H28) -> 0 | J28: =IF($E28<=J$24, $B28/12, 0) -> 0 | K28: =IF($E28<=K$24, $B28/12, 0) -> 0 | L28: =IF($E28<=L$24, $B28/12, 0) -> 0 | M28: =SUM(J28:L28) -> 0 | N28: =IF($E28<=N$24, $B28/12, 0) -> 0 | O28: =IF($E28<=O$24, $B28/12, 0) -> 0 | P28: =IF($E28<=P$24, $B28/12, 0) -> 0 | Q28: =SUM(N28:P28) -> 0 | R28: =IF($E28<=R$24, $B28/12, 0) -> 0 | S28: =IF($E28<=S$24, $B28/12, 0) -> 0 | T28: =IF($E28<=T$24, $B28/12, 0) -> 0 | U28: =SUM(R28:T28) -> 0 | V28: =I28+M28+Q28+U28 -> 0 | W28: =IF($E28<=W$24, $B28/12, 0) -> 0 | X28: =IF($E28<=X$24, $B28/12, 0) -> 0 | Y28: =IF($E28<=Y$24, $B28/12, 0) -> 0 | Z28: =SUM(W28:Y28) -> 0 | AA28: =IF($E28<=AA$24, $B28/12, 0) -> 0 | AB28: =IF($E28<=AB$24, $B28/12, 0) -> 0 | AC28: =IF($E28<=AC$24, $B28/12, 0) -> 0 | AD28: =SUM(AA28:AC28) -> 0 | AE28: =IF($E28<=AE$24, $B28/12, 0) -> 0 | AF28: =IF($E28<=AF$24, $B28/12, 0) -> 0 | AG28: =IF($E28<=AG$24, $B28/12, 0) -> 0 | AH28: =SUM(AE28:AG28) -> 0 | AI28: =IF($E28<=AI$24, $B28/12, 0) -> 0 | AJ28: =IF($E28<=AJ$24, $B28/12, 0) -> 0 | AK28: =IF($E28<=AK$24, $B28/12, 0) -> 0 | AL28: =SUM(AI28:AK28) -> 0 | AM28: =Z28+AD28+AH28+AL28 -> 0
A29: Total: | B29: =SUM(B25:B28) -> 1500 | F29: =SUM(F25:F26) -> 125 | G29: =SUM(G25:G26) -> 125 | H29: =SUM(H25:H26) -> 125 | I29: =SUM(I25:I26) -> 375 | J29: =SUM(J25:J26) -> 125 | K29: =SUM(K25:K26) -> 125 | L29: =SUM(L25:L26) -> 125 | M29: =SUM(M25:M26) -> 375 | ... AM29: =SUM(AM25:AM26) -> 1500
A32: Operations:
A33: Title | B33: Annual | E33: Start Date | F33: 46037 | G33: 46068 | H33: 46096 | I33: Q1 2025 | J33: 46127 | K33: 46157 | L33: 46188 | M33: Q2 2026 | N33: 46218 | O33: 46249 | P33: 46280 | Q33: Q3 2026 | R33: 46310 | S33: 46341 | T33: 46371 | U33: Q4 2026 | V33: FY 2026 | W33: 46402 | X33: 46433 | Y33: 46461 | Z33: Q1 2027 | AA33: 46492 | AB33: 46522 | AC33: 46553 | AD33: Q2 2027 | AE33: 46583 | AF33: 46614 | AG33: 46645 | AH33: Q3 2027 | AI33: 46675 | AJ33: 46706 | AK33: 46736 | AL33: Q4 2027 | AM33: FY 2027
A34: AWS | B34: 0 | E34: 45658 | F34: =IF($E34<=F$33, $B34/12, 0) -> 0 | G34: =IF($E34<=G$33, $B34/12, 0) -> 0 | H34: =IF($E34<=H$33, $B34/12, 0) -> 0 | I34: =SUM(F34:H34) -> 0 | J34: =IF($E34<=J$33, $B34/12, 0) -> 0 | K34: =IF($E34<=K$33, $B34/12, 0) -> 0 | L34: =IF($E34<=L$33, $B34/12, 0) -> 0 | M34: =SUM(J34:L34) -> 0 | N34: =IF($E34<=N$33, $B34/12, 0) -> 0 | O34: =IF($E34<=O$33, $B34/12, 0) -> 0 | P34: =IF($E34<=P$33, $B34/12, 0) -> 0 | Q34: =SUM(N34:P34) -> 0 | R34: =IF($E34<=R$33, $B34/12, 0) -> 0 | S34: =IF($E34<=S$33, $B34/12, 0) -> 0 | T34: =IF($E34<=T$33, $B34/12, 0) -> 0 | U34: =SUM(R34:T34) -> 0 | V34: =I34+M34+Q34+U34 -> 0 | W34: =IF($E34<=W$33, $B34/12, 0) -> 0 | X34: =IF($E34<=X$33, $B34/12, 0) -> 0 | Y34: =IF($E34<=Y$33, $B34/12, 0) -> 0 | Z34: =SUM(W34:Y34) -> 0 | AA34: =IF($E34<=AA$33, $B34/12, 0) -> 0 | AB34: =IF($E34<=AB$33, $B34/12, 0) -> 0 | AC34: =IF($E34<=AC$33, $B34/12, 0) -> 0 | AD34: =SUM(AA34:AC34) -> 0 | AE34: =IF($E34<=AE$33, $B34/12, 0) -> 0 | AF34: =IF($E34<=AF$33, $B34/12, 0) -> 0 | AG34: =IF($E34<=AG$33, $B34/12, 0) -> 0 | AH34: =SUM(AE34:AG34) -> 0 | AI34: =IF($E34<=AI$33, $B34/12, 0) -> 0 | AJ34: =IF($E34<=AJ$33, $B34/12, 0) -> 0 | AK34: =IF($E34<=AK$33, $B34/12, 0) -> 0 | AL34: =SUM(AI34:AK34) -> 0 | AM34: =Z34+AD34+AH34+AL34 -> 0
A35: Other | B35: 0 | E35: 45658 | F35: =IF($E35<=F$33, $B35/12, 0) -> 0 | G35: =IF($E35<=G$33, $B35/12, 0) -> 0 | H35: =IF($E35<=H$33, $B35/12, 0) -> 0 | I35: =SUM(F35:H35) -> 0 | J35: =IF($E35<=J$33, $B35/12, 0) -> 0 | K35: =IF($E35<=K$33, $B35/12, 0) -> 0 | L35: =IF($E35<=L$33, $B35/12, 0) -> 0 | M35: =SUM(J35:L35) -> 0 | N35: =IF($E35<=N$33, $B35/12, 0) -> 0 | O35: =IF($E35<=O$33, $B35/12, 0) -> 0 | P35: =IF($E35<=P$33, $B35/12, 0) -> 0 | Q35: =SUM(N35:P35) -> 0 | R35: =IF($E35<=R$33, $B35/12, 0) -> 0 | S35: =IF($E35<=S$33, $B35/12, 0) -> 0 | T35: =IF($E35<=T$33, $B35/12, 0) -> 0 | U35: =SUM(R35:T35) -> 0 | V35: =I35+M35+Q35+U35 -> 0 | W35: =IF($E35<=W$33, $B35/12, 0) -> 0 | X35: =IF($E35<=X$33, $B35/12, 0) -> 0 | Y35: =IF($E35<=Y$33, $B35/12, 0) -> 0 | Z35: =SUM(W35:Y35) -> 0 | AA35: =IF($E35<=AA$33, $B35/12, 0) -> 0 | AB35: =IF($E35<=AB$33, $B35/12, 0) -> 0 | AC35: =IF($E35<=AC$33, $B35/12, 0) -> 0 | AD35: =SUM(AA35:AC35) -> 0 | AE35: =IF($E35<=AE$33, $B35/12, 0) -> 0 | AF35: =IF($E35<=AF$33, $B35/12, 0) -> 0 | AG35: =IF($E35<=AG$33, $B35/12, 0) -> 0 | AH35: =SUM(AE35:AG35) -> 0 | AI35: =IF($E35<=AI$33, $B35/12, 0) -> 0 | AJ35: =IF($E35<=AJ$33, $B35/12, 0) -> 0 | AK35: =IF($E35<=AK$33, $B35/12, 0) -> 0 | AL35: =SUM(AI35:AK35) -> 0 | AM35: =Z35+AD35+AH35+AL35 -> 0
A36: Legal services | B36: 0 | E36: 45658 | F36: =IF($E36<=F$24, $B36/12, 0) -> 0 | G36: =IF($E36<=G$24, $B36/12, 0) -> 0 | H36: =IF($E36<=H$24, $B36/12, 0) -> 0 | I36: =SUM(F36:H36) -> 0 | J36: =IF($E36<=J$24, $B36/12, 0) -> 0 | K36: =IF($E36<=K$24, $B36/12, 0) -> 0 | L36: =IF($E36<=L$24, $B36/12, 0) -> 0 | M36: =SUM(J36:L36) -> 0 | N36: =IF($E36<=N$24, $B36/12, 0) -> 0 | O36: =IF($E36<=O$24, $B36/12, 0) -> 0 | P36: =IF($E36<=P$24, $B36/12, 0) -> 0 | Q36: =SUM(N36:P36) -> 0 | R36: =IF($E36<=R$24, $B36/12, 0) -> 0 | S36: =IF($E36<=S$24, $B36/12, 0) -> 0 | T36: =IF($E36<=T$24, $B36/12, 0) -> 0 | U36: =SUM(R36:T36) -> 0 | V36: =I36+M36+Q36+U36 -> 0 | W36: =IF($E36<=W$24, $B36/12, 0) -> 0 | X36: =IF($E36<=X$24, $B36/12, 0) -> 0 | Y36: =IF($E36<=Y$24, $B36/12, 0) -> 0 | Z36: =SUM(W36:Y36) -> 0 | AA36: =IF($E36<=AA$24, $B36/12, 0) -> 0 | AB36: =IF($E36<=AB$24, $B36/12, 0) -> 0 | AC36: =IF($E36<=AC$24, $B36/12, 0) -> 0 | AD36: =SUM(AA36:AC36) -> 0 | AE36: =IF($E36<=AE$24, $B36/12, 0) -> 0 | AF36: =IF($E36<=AF$24, $B36/12, 0) -> 0 | AG36: =IF($E36<=AG$24, $B36/12, 0) -> 0 | AH36: =SUM(AE36:AG36) -> 0 | AI36: =IF($E36<=AI$24, $B36/12, 0) -> 0 | AJ36: =IF($E36<=AJ$24, $B36/12, 0) -> 0 | AK36: =IF($E36<=AK$24, $B36/12, 0) -> 0 | AL36: =SUM(AI36:AK36) -> 0 | AM36: =Z36+AD36+AH36+AL36 -> 0
A37: Add more | B37: 0 | E37: 45658 | F37: =IF($E37<=F$24, $B37/12, 0) -> 0 | G37: =IF($E37<=G$24, $B37/12, 0) -> 0 | H37: =IF($E37<=H$24, $B37/12, 0) -> 0 | I37: =SUM(F37:H37) -> 0 | J37: =IF($E37<=J$24, $B37/12, 0) -> 0 | K37: =IF($E37<=K$24, $B37/12, 0) -> 0 | L37: =IF($E37<=L$24, $B37/12, 0) -> 0 | M37: =SUM(J37:L37) -> 0 | N37: =IF($E37<=N$24, $B37/12, 0) -> 0 | O37: =IF($E37<=O$24, $B37/12, 0) -> 0 | P37: =IF($E37<=P$24, $B37/12, 0) -> 0 | Q37: =SUM(N37:P37) -> 0 | R37: =IF($E37<=R$24, $B37/12, 0) -> 0 | S37: =IF($E37<=S$24, $B37/12, 0) -> 0 | T37: =IF($E37<=T$24, $B37/12, 0) -> 0 | U37: =SUM(R37:T37) -> 0 | V37: =I37+M37+Q37+U37 -> 0 | W37: =IF($E37<=W$24, $B37/12, 0) -> 0 | X37: =IF($E37<=X$24, $B37/12, 0) -> 0 | Y37: =IF($E37<=Y$24, $B37/12, 0) -> 0 | Z37: =SUM(W37:Y37) -> 0 | AA37: =IF($E37<=AA$24, $B37/12, 0) -> 0 | AB37: =IF($E37<=AB$24, $B37/12, 0) -> 0 | AC37: =IF($E37<=AC$24, $B37/12, 0) -> 0 | AD37: =SUM(AA37:AC37) -> 0 | AE37: =IF($E37<=AE$24, $B37/12, 0) -> 0 | AF37: =IF($E37<=AF$24, $B37/12, 0) -> 0 | AG37: =IF($E37<=AG$24, $B37/12, 0) -> 0 | AH37: =SUM(AE37:AG37) -> 0 | AI37: =IF($E37<=AI$24, $B37/12, 0) -> 0 | AJ37: =IF($E37<=AJ$24, $B37/12, 0) -> 0 | AK37: =IF($E37<=AK$24, $B37/12, 0) -> 0 | AL37: =SUM(AI37:AK37) -> 0 | AM37: =Z37+AD37+AH37+AL37 -> 0
A38: Total: | B38: =SUM(B34:B37) -> 0 | F38: =SUM(F34:F35) -> 0 | G38: =SUM(G34:G35) -> 0 | H38: =SUM(H34:H35) -> 0 | I38: =SUM(I34:I35) -> 0 | J38: =SUM(J34:J35) -> 0 | K38: =SUM(K34:K35) -> 0 | L38: =SUM(L34:L35) -> 0 | M38: =SUM(M34:M35) -> 0 | ... AM38: =SUM(AM34:AM35) -> 0
A41: Marketing and Advertisements
A42: Title | B42: Annual | E42: Start Date | F42: 46037 | G42: 46068 | H42: 46096 | I42: Q1 2025 | J42: 46127 | K42: 46157 | L42: 46188 | M42: Q2 2026 | N42: 46218 | O42: 46249 | P42: 46280 | Q42: Q3 2026 | R42: 46310 | S42: 46341 | T42: 46371 | U42: Q4 2026 | V42: FY 2026 | W42: 46402 | X42: 46433 | Y42: 46461 | Z42: Q1 2027 | AA42: 46492 | AB42: 46522 | AC42: 46553 | AD42: Q2 2027 | AE42: 46583 | AF42: 46614 | AG42: 46645 | AH42: Q3 2027 | AI42: 46675 | AJ42: 46706 | AK42: 46736 | AL42: Q4 2027 | AM42: FY 2027
A43: Acquisition campaigns | B43: 0 | E43: 45748 | F43: =IF($E43<=F$42, $B43/12, 0) -> 0 | G43: =IF($E43<=G$42, $B43/12, 0) -> 0 | H43: =IF($E43<=H$42, $B43/12, 0) -> 0 | I43: =SUM(F43:H43) -> 0 | J43: =IF($E43<=J$42, $B43/12, 0) -> 0 | K43: =IF($E43<=K$42, $B43/12, 0) -> 0 | L43: =IF($E43<=L$42, $B43/12, 0) -> 0 | M43: =SUM(J43:L43) -> 0 | N43: =IF($E43<=N$42, $B43/12, 0) -> 0 | O43: =IF($E43<=O$42, $B43/12, 0) -> 0 | P43: =IF($E43<=P$42, $B43/12, 0) -> 0 | Q43: =SUM(N43:P43) -> 0 | R43: =IF($E43<=R$42, $B43/12, 0) -> 0 | S43: =IF($E43<=S$42, $B43/12, 0) -> 0 | T43: =IF($E43<=T$42, $B43/12, 0) -> 0 | U43: =SUM(R43:T43) -> 0 | V43: =I43+M43+Q43+U43 -> 0 | W43: =IF($E43<=W$42, $B43/12, 0) -> 0 | X43: =IF($E43<=X$42, $B43/12, 0) -> 0 | Y43: =IF($E43<=Y$42, $B43/12, 0) -> 0 | Z43: =SUM(W43:Y43) -> 0 | AA43: =IF($E43<=AA$42, $B43/12, 0) -> 0 | AB43: =IF($E43<=AB$42, $B43/12, 0) -> 0 | AC43: =IF($E43<=AC$42, $B43/12, 0) -> 0 | AD43: =SUM(AA43:AC43) -> 0 | AE43: =IF($E43<=AE$42, $B43/12, 0) -> 0 | AF43: =IF($E43<=AF$42, $B43/12, 0) -> 0 | AG43: =IF($E43<=AG$42, $B43/12, 0) -> 0 | AH43: =SUM(AE43:AG43) -> 0 | AI43: =IF($E43<=AI$42, $B43/12, 0) -> 0 | AJ43: =IF($E43<=AJ$42, $B43/12, 0) -> 0 | AK43: =IF($E43<=AK$42, $B43/12, 0) -> 0 | AL43: =SUM(AI43:AK43) -> 0 | AM43: =Z43+AD43+AH43+AL43 -> 0
A44: Advertising | B44: 7000 | E44: 46143 | F44: =IF($E44<=F$42, $B44/12, 0) -> 0 | G44: =IF($E44<=G$42, $B44/12, 0) -> 0 | H44: =IF($E44<=H$42, $B44/12, 0) -> 0 | I44: =SUM(F44:H44) -> 0 | J44: =IF($E44<=J$42, $B44/12, 0) -> 0 | K44: =IF($E44<=K$42, $B44/12, 0) -> 583.33333 | L44: =IF($E44<=L$42, $B44/12, 0) -> 583.33333 | M44: =SUM(J44:L44) -> 1166.6667 | N44: =IF($E44<=N$42, $B44/12, 0) -> 583.33333 | O44: =IF($E44<=O$42, $B44/12, 0) -> 583.33333 | P44: =IF($E44<=P$42, $B44/12, 0) -> 583.33333 | Q44: =SUM(N44:P44) -> 1750 | R44: =IF($E44<=R$42, $B44/12, 0) -> 583.33333 | S44: =IF($E44<=S$42, $B44/12, 0) -> 583.33333 | T44: =IF($E44<=T$42, $B44/12, 0) -> 583.33333 | U44: =SUM(R44:T44) -> 1750 | V44: =I44+M44+Q44+U44 -> 4666.6667 | W44: =IF($E44<=W$42, $B44/12, 0) -> 583.33333 | X44: =IF($E44<=X$42, $B44/12, 0) -> 583.33333 | Y44: =IF($E44<=Y$42, $B44/12, 0) -> 583.33333 | Z44: =SUM(W44:Y44) -> 1750 | AA44: =IF($E44<=AA$42, $B44/12, 0) -> 583.33333 | AB44: =IF($E44<=AB$42, $B44/12, 0) -> 583.33333 | AC44: =IF($E44<=AC$42, $B44/12, 0) -> 583.33333 | AD44: =SUM(AA44:AC44) -> 1750 | AE44: =IF($E44<=AE$42, $B44/12, 0) -> 583.33333 | AF44: =IF($E44<=AF$42, $B44/12, 0) -> 583.33333 | AG44: =IF($E44<=AG$42, $B44/12, 0) -> 583.33333 | AH44: =SUM(AE44:AG44) -> 1750 | AI44: =IF($E44<=AI$42, $B44/12, 0) -> 583.33333 | AJ44: =IF($E44<=AJ$42, $B44/12, 0) -> 583.33333 | AK44: =IF($E44<=AK$42, $B44/12, 0) -> 583.33333 | AL44: =SUM(AI44:AK44) -> 1750 | AM44: =Z44+AD44+AH44+AL44 -> 7000
A45: Total: | B45: =SUM(B43:B44) -> 7000 | F45: =SUM(F43:F44) -> 0 | G45: =SUM(G43:G44) -> 0 | H45: =SUM(H43:H44) -> 0 | I45: =SUM(F45:H45) -> 0 | J45: =SUM(J43:J44) -> 0 | K45: =SUM(K43:K44) -> 583.33333 | L45: =SUM(L43:L44) -> 583.33333 | M45: =SUM(J45:L45) -> 1166.6667 | N45: =SUM(N43:N44) -> 583.33333 | O45: =SUM(O43:O44) -> 583.33333 | P45: =SUM(P43:P44) -> 583.33333 | Q45: =SUM(N45:P45) -> 1750 | R45: =SUM(R43:R44) -> 583.33333 | S45: =SUM(S43:S44) -> 583.33333 | T45: =SUM(T43:T44) -> 583.33333 | U45: =SUM(R45:T45) -> 1750 | V45: =I45+M45+Q45+U45 -> 4666.6667 | W45: =SUM(W43:W44) -> 583.33333 | X45: =SUM(X43:X44) -> 583.33333 | Y45: =SUM(Y43:Y44) -> 583.33333 | Z45: =SUM(W45:Y45) -> 1750 | AA45: =SUM(AA43:AA44) -> 583.33333 | AB45: =SUM(AB43:AB44) -> 583.33333 | AC45: =SUM(AC43:AC44) -> 583.33333 | AD45: =SUM(AA45:AC45) -> 1750 | AE45: =SUM(AE43:AE44) -> 583.33333 | AF45: =SUM(AF43:AF44) -> 583.33333 | AG45: =SUM(AG43:AG44) -> 583.33333 | AH45: =SUM(AE45:AG45) -> 1750 | AI45: =SUM(AI43:AI44) -> 583.33333 | AJ45: =SUM(AJ43:AJ44) -> 583.33333 | AK45: =SUM(AK43:AK44) -> 583.33333 | AL45: =SUM(AI45:AK45) -> 1750 | AM45: =Z45+AD45+AH45+AL45 -> 7000
A47: Total costs:
A48: Title | B48: Annual | E48: Start Date | F48: 46037 | G48: 46068 | H48: 46096 | I48: Q1 2025 | J48: 46127 | K48: 46157 | L48: 46188 | M48: Q2 2026 | N48: 46218 | O48: 46249 | P48: 46280 | Q48: Q3 2026 | R48: 46310 | S48: 46341 | T48: 46371 | U48: Q4 2026 | V48: FY 2026 | W48: 46402 | X48: 46433 | Y48: 46461 | Z48: Q1 2027 | AA48: 46492 | AB48: 46522 | AC48: 46553 | AD48: Q2 2027 | AE48: 46583 | AF48: 46614 | AG48: 46645 | AH48: Q3 2027 | AI48: 46675 | AJ48: 46706 | AK48: 46736 | AL48: Q4 2027 | AM48: FY 2027
A49: Total costs | B49: =B19+B29+B38+B45 -> 158500 | F49: =F19+F29+F38+F45 -> 4666.6667 | G49: =G19+G29+G38+G45 -> 4666.6667 | H49: =H19+H29+H38+H45 -> 4666.6667 | I49: =SUM(F49:H49) -> 14000 | J49: =J19+J29+J38+J45 -> 4666.6667 | K49: =K19+K29+K38+K45 -> 5250 | L49: =L19+L29+L38+L45 -> 5250 | M49: =SUM(J49:L49) -> 15166.667 | N49: =N19+N29+N38+N45 -> 14333.333 | O49: =O19+O29+O38+O45 -> 14333.333 | P49: =P19+P29+P38+P45 -> 14333.333 | Q49: =SUM(N49:P49) -> 43000 | R49: =R19+R29+R38+R45 -> 14333.333 | S49: =S19+S29+S38+S45 -> 14333.333 | T49: =T19+T29+T38+T45 -> 14333.333 | U49: =SUM(R49:T49) -> 43000 | V49: =I49+M49+Q49+U49 -> 115166.67 | W49: =W19+W29+W38+W45 -> 14333.333 | X49: =X19+X29+X38+X45 -> 14333.333 | Y49: =Y19+Y29+Y38+Y45 -> 14333.333 | Z49: =SUM(W49:Y49) -> 43000 | AA49: =AA19+AA29+AA38+AA45 -> 14333.333 | AB49: =AB19+AB29+AB38+AB45 -> 14333.333 | AC49: =AC19+AC29+AC38+AC45 -> 14333.333 | AD49: =SUM(AA49:AC49) -> 43000 | AE49: =AE19+AE29+AE38+AE45 -> 14333.333 | AF49: =AF19+AF29+AF38+AF45 -> 14333.333 | AG49: =AG19+AG29+AG38+AG45 -> 14333.333 | AH49: =SUM(AE49:AG49) -> 43000 | AI49: =AI19+AI29+AI38+AI45 -> 14333.333 | AJ49: =AJ19+AJ29+AJ38+AJ45 -> 14333.333 | AK49: =AK19+AK29+AK38+AK45 -> 14333.333 | AL49: =SUM(AI49:AK49) -> 43000 | AM49: =Z49+AD49+AH49+AL49 -> 172000
A52: Runway with no customers (worst case)
...

Sheet App Purchase Revenue
A1: This sheet models revenue from one-time app purchases. Revenue each month = new purchases × app price × (1 − app store fee). Yellow cells are inputs, all others are calculated.
A5: DriveCam One-Time Purchase Revenue
A6: App price ($) | B6: 5 | D6: Yellow highlighted cells are inputs, all others are calculated for you
A7: App store fee (%) | B7: 0.3
A8: Net revenue per download ($) | B8: =B6*(1-B7) -> 3.5
A10: Metric
A11: Monthly app store page visitors | B11: 3000 | C11: =B11*(1+$B$12) -> 3750 | D11: =C11*(1+$B$12) -> 4687.5 | E11: =D11*(1+$B$12) -> 5859.375 | F11: =E11*(1+$B$12) -> 7324.2188 | G11: =F11*(1+$B$12) -> 9155.2734 | H11: =G11*(1+$B$12) -> 11444.092 | I11: =H11*(1+$B$12) -> 14305.115 | J11: =I11*(1+$B$12) -> 17881.393 | ... Y11: =X11*(1+$B$12) -> 508219.77
A12: Monthly visitor growth rate (%) | B12: 0.25
A13: Visitor-to-download conversion rate (%) | B13: 0.1
A14: Total downloads this month | B14: =ROUND(B11*$B$13,0) -> 300 | C14: =ROUND(C11*$B$13,0) -> 375 | D14: =ROUND(D11*$B$13,0) -> 469 | E14: =ROUND(E11*$B$13,0) -> 586 | F14: =ROUND(F11*$B$13,0) -> 732 | G14: =ROUND(G11*$B$13,0) -> 916 | H14: =ROUND(H11*$B$13,0) -> 1144 | I14: =ROUND(I11*$B$13,0) -> 1431 | ... Y14: =ROUND(Y11*$B$13,0) -> 50822
A15: Download-to-purchase conversion rate (%) | B15: 1
A16: New purchases this month | B16: =ROUND(B14*$B$15,0) -> 300 | C16: =ROUND(C14*$B$15,0) -> 375 | D16: =ROUND(D14*$B$15,0) -> 469 | E16: =ROUND(E14*$B$15,0) -> 586 | F16: =ROUND(F14*$B$15,0) -> 732 | G16: =ROUND(G14*$B$15,0) -> 916 | H16: =ROUND(H14*$B$15,0) -> 1144 | I16: =ROUND(I14*$B$15,0) -> 1431 | ... Y16: =ROUND(Y14*$B$15,0) -> 50822
A17: Monthly Revenue ($) | B17: =B16*$B$8 -> 1050 | C17: =C16*$B$8 -> 1312.5 | D17: =D16*$B$8 -> 1641.5 | E17: =E16*$B$8 -> 2051 | F17: =F16*$B$8 -> 2562 | G17: =G16*$B$8 -> 3206 | H17: =H16*$B$8 -> 4004 | I17: =I16*$B$8 -> 5008.5 | ... Y17: =Y16*$B$8 -> 177877
A18: Revenue month-over-month growth (%) | C18: =(C17-B17)/B17 -> 0.25 | D18: =(D17-C17)/C17 -> 0.25066667 | E18: =(E17-D17)/D17 -> 0.24946695 | F18: =(F17-E17)/E17 -> 0.24914676 | G18: =(G17-F17)/F17 -> 0.25136612 | H18: =(H17-G17)/G17 -> 0.2489083 | I18: =(I17-H17)/H17 -> 0.25087413 | J18: =(J17-I17)/I17 -> 0.24947589 | ... Y18: =(Y17-X17)/X17 -> 0.2499877
A19: Total downloads cumulative | B19: =B14 -> 300 | C19: =B19+C14 -> 675 | D19: =C19+D14 -> 1144 | E19: =D19+E14 -> 1730 | F19: =E19+F14 -> 2462 | G19: =F19+G14 -> 3378 | H19: =G19+H14 -> 4522 | I19: =H19+I14 -> 5953 | J19: =I19+J14 -> 7741 | ... Y19: =X19+Y14 -> 252911
A20: Total Revenue cumulative ($) | B20: =B17 -> 1050 | C20: =B20+C17 -> 2362.5 | D20: =C20+D17 -> 4004 | E20: =D20+E17 -> 6055 | F20: =E20+F17 -> 8617 | G20: =F20+G17 -> 11823 | H20: =G20+H17 -> 15827 | I20: =H20+I17 -> 20835.5 | J20: =I20+J17 -> 27093.5 | ... Y20: =X20+Y17 -> 885188.5

Sheet Profit and Loss (P&L)
A1: This sheet is a profit and loss modeling sheet that demonstrates your profit over time. It also has a feature to inject investment cash and an estimate of your companies valuation assuming a 7x revenue valuation.
B3: 46037 | C3: 46068 | D3: 46099 | E3: 46130 | F3: 46161 | G3: 46192 | H3: 46223 | I3: 46254 | J3: 46285 | K3: 46316 | L3: 46347 | M3: 46378 | N3: 46402 | O3: 46433 | P3: 46464 | Q3: 46495 | R3: 46526 | S3: 46557 | T3: 46588 | U3: 46619 | V3: 46650 | W3: 46681 | X3: 46712 | Y3: 46743
A4: Expenses | B4: =Expenses!F49 -> 4666.6667 | C4: =Expenses!G49 -> 4666.6667 | D4: =Expenses!H49 -> 4666.6667 | E4: =Expenses!J49 -> 4666.6667 | F4: =Expenses!K49 -> 5250 | G4: =Expenses!L49 -> 5250 | H4: =Expenses!N49 -> 14333.333 | I4: =Expenses!O49 -> 14333.333 | J4: =Expenses!P49 -> 14333.333 | K4: =Expenses!R49 -> 14333.333 | L4: =Expenses!S49 -> 14333.333 | M4: =Expenses!T49 -> 14333.333 | N4: =Expenses!W49 -> 14333.333 | O4: =Expenses!X49 -> 14333.333 | P4: =Expenses!Y49 -> 14333.333 | Q4: =Expenses!AA49 -> 14333.333 | R4: =Expenses!AB49 -> 14333.333 | S4: =Expenses!AC49 -> 14333.333 | T4: =Expenses!AE49 -> 14333.333 | U4: =Expenses!AF49 -> 14333.333 | V4: =Expenses!AG49 -> 14333.333 | W4: =Expenses!AI49 -> 14333.333 | X4: =Expenses!AJ49 -> 14333.333 | Y4: =Expenses!AK49 -> 14333.333
A5: Revenue | B5: ='App Purchase Revenue'!B17 -> 1050 | C5: ='App Purchase Revenue'!C17 -> 1312.5 | D5: ='App Purchase Revenue'!D17 -> 1641.5 | E5: ='App Purchase Revenue'!E17 -> 2051 | F5: ='App Purchase Revenue'!F17 -> 2562 | G5: ='App Purchase Revenue'!G17 -> 3206 | H5: ='App Purchase Revenue'!H17 -> 4004 | I5: ='App Purchase Revenue'!I17 -> 5008.5 | ... Y5: ='App Purchase Revenue'!Y17 -> 177877
A6: Profit | B6: =B5-B4 -> -3616.6667 | C6: =C5-C4 -> -3354.1667 | D6: =D5-D4 -> -3025.1667 | E6: =E5-E4 -> -2615.6667 | F6: =F5-F4 -> -2688 | G6: =G5-G4 -> -2044 | H6: =H5-H4 -> -10329.333 | I6: =I5-I4 -> -9324.8333 | ... Y6: =Y5-Y4 -> 163543.67
A7: Cash Balance | B7: =Expenses!B2+B6+B8 -> 96383.333 | C7: =B7+C6+C8 -> 93029.167 | D7: =C7+D6+D8 -> 90004 | E7: =D7+E6+E8 -> 87388.333 | F7: =E7+F6+F8 -> 84700.333 | G7: =F7+G6+G8 -> 82656.333 | H7: =G7+H6+H8 -> 172327 | I7: =H7+I6+I8 -> 163002.17 | J7: =I7+J6+J8 -> 154926.83 | ... Y7: =X7+Y6+Y8 -> 798021.83
A8: Investment | H8: 100000
A9: Valuation Estimate (7x Rev) | B9: =7*B5 -> 7350 | C9: =7*C5 -> 9187.5 | D9: =7*D5 -> 11490.5 | E9: =7*E5 -> 14357 | F9: =7*F5 -> 17934 | G9: =7*G5 -> 22442 | H9: =7*H5 -> 28028 | I9: =7*I5 -> 35059.5 | ... Y9: =7*Y5 -> 1245139
B11: FY 2026 | C11: FY 2027
A12: Annual Expenses | B12: =Expenses!V49 -> 115166.67 | C12: =Expenses!AM49 -> 172000
A13: Annual Revenue | B13: =SUM(B5:M5) -> 56917 | C13: =SUM(N5:Y5) -> 828271.5
A14: Profit | B14: =B13-B12 -> -58249.667 | C14: =C13-C12 -> 656271.5
A15: Cash Balance | B15: =M7 -> 141750.33 | C15: =Y7 -> 798021.83
